<sdf version='1.7'>
  <model name='tortoisebot_simple'>
    <link name = 'base_footprint'/>
    <link name='base_link'>
      <inertial>
        <pose>-0.030581 -0.00041 0.079436 0 -0 0</pose>
        <mass>1.1622</mass>
        <inertia>
          <ixx>0.00430576</ixx>
          <ixy>-1.20273e-05</ixy>
          <ixz>-5.03252e-05</ixz>
          <iyy>0.00405645</iyy>
          <iyz>1.90146e-05</iyz>
          <izz>0.0022887</izz>
        </inertia>
      </inertial>
      <collision name='base_link_collision'>
        <pose>0 0 0 0 -0 0</pose>
        <geometry>
          <mesh>
            <scale>0.001 0.001 0.001</scale>
            <uri>file:///home/pacman/tortoisebot_rb/install/tortoisebot_description/share/tortoisebot_description/models/meshes/base_link.dae</uri>
          </mesh>
        </geometry>
        <surface>
          <contact>
            <ode/>
          </contact>
          <friction>
            <ode>
              <mu>0.2</mu>
              <mu2>0.2</mu2>
            </ode>
          </friction>
        </surface>
      </collision>
      <collision name='base_link_fixed_joint_lump__camera_holder_collision_1'>
        <pose>0 0 0 0 -0 0</pose>
        <geometry>
          <mesh>
            <scale>0.001 0.001 0.001</scale>
            <uri>file:///home/pacman/tortoisebot_rb/install/tortoisebot_description/share/tortoisebot_description/models/meshes/camera_holder.dae</uri>
          </mesh>
        </geometry>
        <surface>
          <contact>
            <ode/>
          </contact>
          <friction>
            <ode>
              <mu>0.2</mu>
              <mu2>0.2</mu2>
            </ode>
          </friction>
        </surface>
      </collision>
      <collision name='base_link_fixed_joint_lump__camera_link_collision_2'>
        <pose>0 0 0 0 -0 0</pose>
        <geometry>
          <mesh>
            <scale>0.001 0.001 0.001</scale>
            <uri>file:///home/pacman/tortoisebot_rb/install/tortoisebot_description/share/tortoisebot_description/models/meshes/camera_link.dae</uri>
          </mesh>
        </geometry>
        <surface>
          <contact>
            <ode/>
          </contact>
          <friction>
            <ode>
              <mu>0.2</mu>
              <mu2>0.2</mu2>
            </ode>
          </friction>
        </surface>
      </collision>
      <collision name='base_link_fixed_joint_lump__castor_wheel_collision_3'>
        <pose>0 0 0 0 -0 0</pose>
        <geometry>
          <mesh>
            <scale>0.001 0.001 0.001</scale>
            <uri>file:///home/pacman/tortoisebot_rb/install/tortoisebot_description/share/tortoisebot_description/models/meshes/castor_wheel.dae</uri>
          </mesh>
        </geometry>
        <surface>
          <contact>
            <ode/>
          </contact>
          <friction>
            <ode>
              <mu>0.1</mu>
              <mu2>0.1</mu2>
            </ode>
          </friction>
        </surface>
      </collision>
      <collision name='base_link_fixed_joint_lump__lidar_collision_4'>
        <pose>0 0 0 0 -0 0</pose>
        <geometry>
          <mesh>
            <scale>0.001 0.001 0.001</scale>
            <uri>file:///home/pacman/tortoisebot_rb/install/tortoisebot_description/share/tortoisebot_description/models/meshes/lidar.dae</uri>
          </mesh>
        </geometry>
        <surface>
          <contact>
            <ode/>
          </contact>
          <friction>
            <ode>
              <mu>0.2</mu>
              <mu2>0.2</mu2>
            </ode>
          </friction>
        </surface>
      </collision>
      <visual name='base_link_visual'>
        <pose>0 0 0 0 -0 0</pose>
        <geometry>
          <mesh>
            <scale>0.001 0.001 0.001</scale>
            <uri>file:///home/pacman/tortoisebot_rb/install/tortoisebot_description/share/tortoisebot_description/models/meshes/base_link.dae</uri>
          </mesh>
        </geometry>
      </visual>
      <visual name='base_link_fixed_joint_lump__camera_holder_visual_1'>
        <pose>0 0 0 0 -0 0</pose>
        <geometry>
          <mesh>
            <scale>0.001 0.001 0.001</scale>
            <uri>file:///home/pacman/tortoisebot_rb/install/tortoisebot_description/share/tortoisebot_description/models/meshes/camera_holder.dae</uri>
          </mesh>
        </geometry>
      </visual>
      <visual name='base_link_fixed_joint_lump__camera_link_visual_2'>
        <pose>0 0 0 0 -0 0</pose>
        <geometry>
          <mesh>
            <scale>0.001 0.001 0.001</scale>
            <uri>file:///home/pacman/tortoisebot_rb/install/tortoisebot_description/share/tortoisebot_description/models/meshes/camera_link.dae</uri>
          </mesh>
        </geometry>
      </visual>
      <visual name='base_link_fixed_joint_lump__castor_wheel_visual_3'>
        <pose>0 0 0 0 -0 0</pose>
        <geometry>
          <mesh>
            <scale>0.001 0.001 0.001</scale>
            <uri>file:///home/pacman/tortoisebot_rb/install/tortoisebot_description/share/tortoisebot_description/models/meshes/castor_wheel.dae</uri>
          </mesh>
        </geometry>
      </visual>
      <visual name='base_link_fixed_joint_lump__lidar_visual_4'>
        <pose>0 0 0 0 -0 0</pose>
        <geometry>
          <mesh>
            <scale>0.001 0.001 0.001</scale>
            <uri>file:///home/pacman/tortoisebot_rb/install/tortoisebot_description/share/tortoisebot_description/models/meshes/lidar.dae</uri>
          </mesh>
        </geometry>
      </visual>
      <gravity>1</gravity>
      <sensor name='raspberrypi_camera' type='camera'>
        <update_rate>30</update_rate>
        <camera name='raspberrypi_camera'>
          <horizontal_fov>0.933751</horizontal_fov>
          <image>
            <width>410</width>
            <height>308</height>
            <format>R8G8B8</format>
          </image>
          <clip>
            <near>0.002</near>
            <far>300</far>
          </clip>
          <noise>
            <type>gaussian</type>
            <mean>0</mean>
            <stddev>0.007</stddev>
          </noise>
        </camera>
        <plugin name='camera_controller_pi' filename='libgazebo_ros_camera.so'>
          <alwaysOn>1</alwaysOn>
          <updateRate>0.0</updateRate>
          <cameraName>/camera</cameraName>
          <imageTopicName>/raspicam_node/image</imageTopicName>
          <cameraInfoTopicName>camera_info</cameraInfoTopicName>
          <frameName>camera_link</frameName>
          <hackBaseline>0.07</hackBaseline>
          <distortionK1>0.0</distortionK1>
          <distortionK2>0.0</distortionK2>
          <distortionK3>0.0</distortionK3>
          <distortionT1>0.0</distortionT1>
          <distortionT2>0.0</distortionT2>
        </plugin>
        <pose>0.05025 1e-05 0.133907 0 -0 0</pose>
      </sensor>
      <sensor name='ydlidar' type='ray'>
        <always_on>1</always_on>
        <visualize>0</visualize>
        <update_rate>10</update_rate>
        <ray>
          <scan>
            <horizontal>
              <samples>720</samples>
              <resolution>1</resolution>
              <min_angle>-3.14</min_angle>
              <max_angle>3.14</max_angle>
            </horizontal>
          </scan>
          <range>
            <min>0.05</min>
            <max>20</max>
            <resolution>0.015</resolution>
          </range>
          <noise>
            <type>gaussian</type>
            <mean>0</mean>
            <stddev>0.01</stddev>
          </noise>
        </ray>
        <plugin name='ttb_lidar' filename='libgazebo_ros_ray_sensor.so'>
          <ros>
            <remapping>~/out:=scan</remapping>
          </ros>
          <output_type>sensor_msgs/LaserScan</output_type>
          <frame_name>lidar</frame_name>
        </plugin>
        <pose>-0.03275 0 0.167 0 -0 0</pose>
      </sensor>
    </link>
    <joint name='wheel_left_joint' type='revolute'>
      <pose relative_to='base_link'>-0.000197 0.0778 0.032453 0 -0 0</pose>
      <parent>base_link</parent>
      <child>wheel_left</child>
      <axis>
        <xyz>0 1 0</xyz>
        <limit>
          <lower>-1e+16</lower>
          <upper>1e+16</upper>
        </limit>
        <dynamics>
          <spring_reference>0</spring_reference>
          <spring_stiffness>0</spring_stiffness>
        </dynamics>
      </axis>
    </joint>
    <link name='wheel_left'>
      <pose relative_to='wheel_left_joint'>0 0 0 0 -0 0</pose>
      <inertial>
        <pose>-0 0.008993 -0 0 -0 0</pose>
        <mass>0.0435594</mass>
        <inertia>
          <ixx>1.9e-05</ixx>
          <ixy>0</ixy>
          <ixz>0</ixz>
          <iyy>3.3e-05</iyy>
          <iyz>0</iyz>
          <izz>1.9e-05</izz>
        </inertia>
      </inertial>
      <collision name='wheel_left_collision'>
        <pose>0.000197 -0.0778 -0.032453 0 -0 0</pose>
        <geometry>
          <mesh>
            <scale>0.001 0.001 0.001</scale>
            <uri>file:///home/pacman/tortoisebot_rb/install/tortoisebot_description/share/tortoisebot_description/models/meshes/wheel_left.dae</uri>
          </mesh>
        </geometry>
        <surface>
          <contact>
            <ode>
              <kp>500000</kp>
              <kd>10</kd>
              <min_depth>0.001</min_depth>
            </ode>
          </contact>
          <friction>
            <ode>
              <mu>1</mu>
              <mu2>1</mu2>
            </ode>
          </friction>
        </surface>
      </collision>
      <visual name='wheel_left_visual'>
        <pose>0.000197 -0.0778 -0.032453 0 -0 0</pose>
        <geometry>
          <mesh>
            <scale>0.001 0.001 0.001</scale>
            <uri>file:///home/pacman/tortoisebot_rb/install/tortoisebot_description/share/tortoisebot_description/models/meshes/wheel_left.dae</uri>
          </mesh>
        </geometry>
      </visual>
    </link>
    <joint name='wheel_right_joint' type='revolute'>
      <pose relative_to='base_link'>0.0001 -0.0778 0.032453 0 -0 0</pose>
      <parent>base_link</parent>
      <child>wheel_right</child>
      <axis>
        <xyz>0 1 0</xyz>
        <limit>
          <lower>-1e+16</lower>
          <upper>1e+16</upper>
        </limit>
        <dynamics>
          <spring_reference>0</spring_reference>
          <spring_stiffness>0</spring_stiffness>
        </dynamics>
      </axis>
    </joint>
    <link name='wheel_right'>
      <pose relative_to='wheel_right_joint'>0 0 0 0 -0 0</pose>
      <inertial>
        <pose>0 -0.008992 -0 0 -0 0</pose>
        <mass>0.0435594</mass>
        <inertia>
          <ixx>1.9e-05</ixx>
          <ixy>0</ixy>
          <ixz>0</ixz>
          <iyy>3.3e-05</iyy>
          <iyz>0</iyz>
          <izz>1.9e-05</izz>
        </inertia>
      </inertial>
      <collision name='wheel_right_collision'>
        <pose>-0.0001 0.0778 -0.032453 0 -0 0</pose>
        <geometry>
          <mesh>
            <scale>0.001 0.001 0.001</scale>
            <uri>file:///home/pacman/tortoisebot_rb/install/tortoisebot_description/share/tortoisebot_description/models/meshes/wheel_right.dae</uri>
          </mesh>
        </geometry>
        <surface>
          <contact>
            <ode>
              <kp>500000</kp>
              <kd>10</kd>
              <min_depth>0.001</min_depth>
            </ode>
          </contact>
          <friction>
            <ode>
              <mu>1</mu>
              <mu2>1</mu2>
            </ode>
          </friction>
        </surface>
      </collision>
      <visual name='wheel_right_visual'>
        <pose>-0.0001 0.0778 -0.032453 0 -0 0</pose>
        <geometry>
          <mesh>
            <scale>0.001 0.001 0.001</scale>
            <uri>file:///home/pacman/tortoisebot_rb/install/tortoisebot_description/share/tortoisebot_description/models/meshes/wheel_right.dae</uri>
          </mesh>
        </geometry>
      </visual>
    </link>
    <static>0</static>
        <plugin name="turtlebot3_diff_drive" filename="libgazebo_ros_diff_drive.so">

      <ros>
        <!-- <namespace>/robot0</namespace> -->
        <remapping>/tf:=tf</remapping>
      </ros>

      <update_rate>30</update_rate>
      <left_joint>wheel_left_joint</left_joint>
      <right_joint>wheel_right_joint</right_joint>

      <wheel_separation>0.287</wheel_separation>
      <wheel_diameter>0.066</wheel_diameter>

      <max_wheel_torque>20</max_wheel_torque>
      <max_wheel_acceleration>1.0</max_wheel_acceleration>

      <command_topic>cmd_vel</command_topic>

      <publish_odom>true</publish_odom>
      <publish_odom_tf>true</publish_odom_tf>
      <publish_wheel_tf>false</publish_wheel_tf>

      <odometry_topic>odom</odometry_topic>
      <odometry_frame>odom</odometry_frame>
      <robot_base_frame>base_footprint</robot_base_frame>

    </plugin>

    <joint name='base_joint_mine' type='fixed'>
      <parent>base_footprint</parent>
      <child>base_link</child>
    </joint>
  </model>
</sdf>
